Traceback (most recent call last):
  File "/home/oscar/gdial/venv/bin/uvicorn", line 8, in <module>
    sys.exit(main())
             ^^^^^^
  File "/home/oscar/gdial/venv/lib/python3.12/site-packages/click/core.py", line 1161, in __call__
    return self.main(*args, **kwargs)
           ^^^^^^^^^^^^^^^^^^^^^^^^^^
  File "/home/oscar/gdial/venv/lib/python3.12/site-packages/click/core.py", line 1082, in main
    rv = self.invoke(ctx)
         ^^^^^^^^^^^^^^^^
  File "/home/oscar/gdial/venv/lib/python3.12/site-packages/click/core.py", line 1443, in invoke
    return ctx.invoke(self.callback, **ctx.params)
           ^^^^^^^^^^^^^^^^^^^^^^^^^^^^^^^^^^^^^^^
  File "/home/oscar/gdial/venv/lib/python3.12/site-packages/click/core.py", line 788, in invoke
    return __callback(*args, **kwargs)
           ^^^^^^^^^^^^^^^^^^^^^^^^^^^
  File "/home/oscar/gdial/venv/lib/python3.12/site-packages/uvicorn/main.py", line 412, in main
    run(
  File "/home/oscar/gdial/venv/lib/python3.12/site-packages/uvicorn/main.py", line 579, in run
    server.run()
  File "/home/oscar/gdial/venv/lib/python3.12/site-packages/uvicorn/server.py", line 65, in run
    return asyncio.run(self.serve(sockets=sockets))
           ^^^^^^^^^^^^^^^^^^^^^^^^^^^^^^^^^^^^^^^^
  File "/usr/lib/python3.12/asyncio/runners.py", line 194, in run
    return runner.run(main)
           ^^^^^^^^^^^^^^^^
  File "/usr/lib/python3.12/asyncio/runners.py", line 118, in run
    return self._loop.run_until_complete(task)
           ^^^^^^^^^^^^^^^^^^^^^^^^^^^^^^^^^^^
  File "uvloop/loop.pyx", line 1518, in uvloop.loop.Loop.run_until_complete
  File "/home/oscar/gdial/venv/lib/python3.12/site-packages/uvicorn/server.py", line 69, in serve
    await self._serve(sockets)
  File "/home/oscar/gdial/venv/lib/python3.12/site-packages/uvicorn/server.py", line 76, in _serve
    config.load()
  File "/home/oscar/gdial/venv/lib/python3.12/site-packages/uvicorn/config.py", line 434, in load
    self.loaded_app = import_from_string(self.app)
                      ^^^^^^^^^^^^^^^^^^^^^^^^^^^^
  File "/home/oscar/gdial/venv/lib/python3.12/site-packages/uvicorn/importer.py", line 19, in import_from_string
    module = importlib.import_module(module_str)
             ^^^^^^^^^^^^^^^^^^^^^^^^^^^^^^^^^^^
  File "/usr/lib/python3.12/importlib/__init__.py", line 90, in import_module
    return _bootstrap._gcd_import(name[level:], package, level)
           ^^^^^^^^^^^^^^^^^^^^^^^^^^^^^^^^^^^^^^^^^^^^^^^^^^^^
  File "<frozen importlib._bootstrap>", line 1387, in _gcd_import
  File "<frozen importlib._bootstrap>", line 1360, in _find_and_load
  File "<frozen importlib._bootstrap>", line 1331, in _find_and_load_unlocked
  File "<frozen importlib._bootstrap>", line 935, in _load_unlocked
  File "<frozen importlib._bootstrap_external>", line 995, in exec_module
  File "<frozen importlib._bootstrap>", line 488, in _call_with_frames_removed
  File "/home/oscar/gdial/app/api.py", line 4, in <module>
    from .database import create_db_and_tables, get_session
  File "/home/oscar/gdial/app/database.py", line 4, in <module>
    settings = get_settings()
               ^^^^^^^^^^^^^^
  File "/home/oscar/gdial/app/config.py", line 26, in get_settings
    return Settings()
           ^^^^^^^^^^
  File "/home/oscar/gdial/venv/lib/python3.12/site-packages/pydantic_settings/main.py", line 167, in __init__
    super().__init__(
  File "/home/oscar/gdial/venv/lib/python3.12/site-packages/pydantic/main.py", line 253, in __init__
    validated_self = self.__pydantic_validator__.validate_python(data, self_instance=self)
                     ^^^^^^^^^^^^^^^^^^^^^^^^^^^^^^^^^^^^^^^^^^^^^^^^^^^^^^^^^^^^^^^^^^^^^
pydantic_core._pydantic_core.ValidationError: 1 validation error for Settings
openai_api_key
  Extra inputs are not permitted [type=extra_forbidden, input_value='sk-proj-OEpUSOPJOmYNDLPm...T2-aYYj32_TvBvOOeOrNbcA', input_type=str]
    For further information visit https://errors.pydantic.dev/2.11/v/extra_forbidden
